<?xml version="1.0" encoding="utf-8"?>

<robot
  name="chess_rob">
  <link
    name="base_link">
    <inertial>
      <origin
        xyz="-0.015217243894891 1.33674799181194E-08 0.0349095660299761"
        rpy="0 0 0" />
      <mass
        value="0.242925533930054" />
      <inertia
        ixx="0.000184514361836117"
        ixy="-6.56879521762788E-08"
        ixz="-8.40471453675092E-06"
        iyy="0.000308044865573332"
        iyz="7.17644794224948E-12"
        izz="0.000348230702382964" />
    </inertial>
    <visual>
      <origin
        xyz="0 0 0"
        rpy="0 0 0" />
      <geometry>
        <mesh
          filename="/home/omar/mambaforge/envs/ros_env/gp_ws/src/chess_rob/meshes/visual/base_link.STL" />
      </geometry>
      <material
        name="">
        <color
          rgba="0.752941176470588 0.752941176470588 0.752941176470588 1" />
      </material>
    </visual>
    <collision>
      <origin
        xyz="0 0 0"
        rpy="0 0 0" />
      <geometry>
        <mesh
          filename="/home/omar/mambaforge/envs/ros_env/gp_ws/src/chess_rob/meshes/collision/base_link.STL" />
      </geometry>
    </collision>
  </link>
  <link
    name="link_1">
    <inertial>
      <origin
        xyz="-0.000606604801845462 0.000544256660138659 0.0309541889481369"
        rpy="0 0 0" />
      <mass
        value="0.165452367760892" />
      <inertia
        ixx="0.000319019027558372"
        ixy="-2.56730533017839E-06"
        ixz="8.60884430980357E-07"
        iyy="0.000174178835891692"
        iyz="-7.48100720278735E-06"
        izz="0.000334430345588851" />
    </inertial>
    <visual>
      <origin
        xyz="0 0 0"
        rpy="0 0 0" />
      <geometry>
        <mesh
          filename="/home/omar/mambaforge/envs/ros_env/gp_ws/src/chess_rob/meshes/visual/link_1.STL" />
      </geometry>
      <material
        name="">
        <color
          rgba="0.752941176470588 0.752941176470588 0.752941176470588 1" />
      </material>
    </visual>
    <collision>
      <origin
        xyz="0 0 0"
        rpy="0 0 0" />
      <geometry>
        <mesh
          filename="/home/omar/mambaforge/envs/ros_env/gp_ws/src/chess_rob/meshes/collision/link_1.STL" />
      </geometry>
    </collision>
  </link>
  <joint
    name="joint_1"
    type="continuous">
    <origin
      xyz="0 0 0.079"
      rpy="0 0 0" />
    <parent
      link="base_link" />
    <child
      link="link_1" />
    <axis
      xyz="0 0 -1" />
  </joint>
  <link
    name="link_2">
    <inertial>
      <origin
        xyz="-1.69017261852922E-08 -0.000945344060170763 0.103491004754061"
        rpy="0 0 0" />
      <mass
        value="0.110239166528901" />
      <inertia
        ixx="0.000645214897942635"
        ixy="-2.1691055188587E-12"
        ixz="-2.08689181194865E-10"
        iyy="0.000665314861067016"
        iyz="-1.28048946872329E-06"
        izz="2.08661229293727E-05" />
    </inertial>
    <visual>
      <origin
        xyz="0 0 0"
        rpy="0 0 0" />
      <geometry>
        <mesh
          filename="/home/omar/mambaforge/envs/ros_env/gp_ws/src/chess_rob/meshes/visual/link_2.STL" />
      </geometry>
      <material
        name="">
        <color
          rgba="0.752941176470588 0.752941176470588 0.752941176470588 1" />
      </material>
    </visual>
    <collision>
      <origin
        xyz="0 0 0"
        rpy="0 0 0" />
      <geometry>
        <mesh
          filename="/home/omar/mambaforge/envs/ros_env/gp_ws/src/chess_rob/meshes/collision/link_2.STL" />
      </geometry>
    </collision>
  </link>
  <joint
    name="joint_2"
    type="continuous">
    <origin
      xyz="0 -0.026124 0.068999"
      rpy="0 -0.697 0" />
    <parent
      link="link_1" />
    <child
      link="link_2" />
    <axis
      xyz="0 1 0" />
    <limit
    lower="0"
    upper="0" />

  </joint>
  <link
    name="link_3">
    <inertial>
      <origin
        xyz="-3.69654537563102E-07 -0.00028797436439582 0.0692637508407093"
        rpy="0 0 0" />
      <mass
        value="0.0586792348761411" />
      <inertia
        ixx="0.000199414999682554"
        ixy="3.30496081031023E-10"
        ixz="1.64091696957926E-12"
        iyy="0.00020384558759879"
        iyz="4.75321439278164E-08"
        izz="6.74770658461029E-06" />
    </inertial>
    <visual>
      <origin
        xyz="0 0 0"
        rpy="0 0 0" />
      <geometry>
        <mesh
          filename="/home/omar/mambaforge/envs/ros_env/gp_ws/src/chess_rob/meshes/visual/link_3.STL" />
      </geometry>
      <material
        name="">
        <color
          rgba="0.752941176470588 0.752941176470588 0.752941176470588 1" />
      </material>
    </visual>
    <collision>
      <origin
        xyz="0 0 0"
        rpy="0 0 0" />
      <geometry>
        <mesh
          filename="/home/omar/mambaforge/envs/ros_env/gp_ws/src/chess_rob/meshes/collision/link_3.STL" />
      </geometry>
    </collision>
  </link>
  <joint
    name="joint_3"
    type="continuous">
    <origin
      xyz="0 0 0.2195"
      rpy="0 2.895 0" />
    <parent
      link="link_2" />
    <child
      link="link_3" />
    <axis
      xyz="0 -1 0" />
      <limit
    lower="0"
    upper="-3.14159" />

  </joint>
  <link
    name="link_4">
    <inertial>
      <origin
        xyz="0.000132107659803454 -1.88106667816882E-05 -0.0858466150623816"
        rpy="0 0 0" />
      <mass
        value="0.0782399819940314" />
      <inertia
        ixx="9.53988185360244E-06"
        ixy="7.41120076252732E-09"
        ixz="-5.20274626001282E-08"
        iyy="9.8647213536698E-06"
        iyz="9.46197536367817E-09"
        izz="6.12772552030606E-06" />
    </inertial>
    <visual>
      <origin
        xyz="0 0 0"
        rpy="0 0 0" />
      <geometry>
        <mesh
          filename="/home/omar/mambaforge/envs/ros_env/gp_ws/src/chess_rob/meshes/visual/link_4.STL" />
      </geometry>
      <material
        name="">
        <color
          rgba="0.752941176470588 0.752941176470588 0.752941176470588 1" />
      </material>
    </visual>
    <collision>
      <origin
        xyz="0 0 0"
        rpy="0 0 0" />
      <geometry>
        <mesh
          filename="/home/omar/mambaforge/envs/ros_env/gp_ws/src/chess_rob/meshes/collision/link_4.STL" />
      </geometry>
    </collision>
  </link>
  <joint
    name="joint_4"
    type="continuous">
    <origin
      xyz="0 0 0.155"
      rpy="0 0 0" />
    <parent
      link="link_3" />
    <child
      link="link_4" />
    <axis
      xyz="0 -1 0" />

  </joint>



</robot>
